Workbook

Sheet PARAMETRES
A1: PARAMÈTRES DU PROJET — Saisir ici, tout se propage automatiquement
A2: Texte bleu = saisie | Texte vert = lien auto | Texte noir = formule
A4: Nom du projet | D4: TAUX DE CHARGES | E4: Taux
A5: Nom de l'association porteuse | D5: Intermittents GUSO (tout compris) | E5: 0.4
A6: SIRET | D6: Intermittents DPAE | E6: 0.46
A7: N° licence entrepreneur du spectacle | D7: Salariés CDI/CDD | E7: 0.43
A8: Date de début | D8: Artistes-auteurs contrib. diffuseur | E8: 0.011
A9: Date de fin | D9: Taux horaire bénévolat SMIC | E9: 11.88
A10: Lieu(x) de réalisation
A11: Code appel à projets (ex: HHP26S2)
A13: STRUCTURE PORTEUSE
A14: Responsable légal
A15: Fonction
A16: Email
A17: Téléphone
A18: Adresse siège

Sheet BUDGET MAITRE
A1: BUDGET PRÉVISIONNEL — SUIVI INTERNE DÉTAILLÉ
A2: Projet : | B2: =PARAMETRES!B4 -> 0 | D2: Association : | E2: =PARAMETRES!B5 -> 0
A4: CHARGES | D4: PRODUITS / RECETTES
A5: CHARGES DIRECTES | D5: Ventes et recettes propres
A6: Achats | D6: Ventes produits / prestations
A7: Services : captation, photos, outils | D7: Concours publics / prix
A8: Fournitures : trophées, collation | D8: Billetterie
A9: Autres achats | D9: Autres recettes
A10: s/t Achats | B10: =SUM(B7:B9) -> 0 | D10: s/t Ventes et recettes propres | E10: =SUM(E6:E9) -> 0
A11: Services extérieurs | D11: Subventions publiques
A12: Locations salles et matériel | D12: État — ministères / DRAC
A13: Assurance | D13: Région(s)
A14: Documentation | D14: Département(s)
A15: Communication et ateliers | D15: Commune(s) / Mairie
A16: Médiation post-projet | D16: Ville de Paris (AAP Hip-Hop)
A17: s/t Services extérieurs | B17: =SUM(B12:B16) -> 0 | D17: Organismes sociaux (CAF…)
A18: Autres services extérieurs | D18: Fonds européens
A19: Rémunérations / honoraires coordination | D19: Autres établissements publics
A20: Publicité et publication | D20: s/t Subventions publiques | E20: =SUM(E12:E19) -> 0
A21: Autres | D21: Financements privés
A22: s/t Autres services extérieurs | B22: =SUM(B19:B21) -> 0 | D22: Mécénat / fondations
A23: Impôts et taxes | D23: Partenaires culturels privés
A24: Taxes diverses | D24: SACEM, ADAMI, SPEDIDAM…
A25: s/t Impôts et taxes | B25: =SUM(B24:B24) -> 0 | D25: Autres
A26: Charges exceptionnelles | D26: s/t Financements privés | E26: =SUM(E22:E25) -> 0
A27: Imprévus | D27: Autres produits
A28: s/t Charges exceptionnelles | B28: =SUM(B27:B27) -> 0 | D28: Cotisations / dons / legs
A29: CHARGES INDIRECTES | D29: Produits exceptionnels
A30: Charges fixes affectées au projet | D30: Transferts de charges
A31: Quote-part loyer / locaux | D31: s/t Autres produits | E31: =SUM(E28:E30) -> 0
A32: Quote-part télécoms | D32: Ressources affectées
A33: Quote-part comptabilité | D33: Ressources propres affectées
A34: s/t Charges fixes affectées au p | B34: =SUM(B31:B33) -> 0 | D34: s/t Ressources affectées | E34: =SUM(E33:E33) -> 0
A35: TOTAL DES CHARGES | B35: =B10+B17+B22+B25+B28+B34 -> 0 | D35: TOTAL DES PRODUITS | E35: =E10+E20+E26+E31+E34 -> 0
A37: =IF(ABS(B35-E35)>1,"⚠️ ÉCART : "&TEXT(ABS(B35-E35),"#,##0")&" €","✅ Budget équilibré — "&TEXT(B35,"#,##0")&" €") -> ✅ Budget équilibré — 0 €
A38: Mise à disp. gratuite de biens/services
A39: Personnel bénévole
A40: Total contributions volontaires | B40: =SUM(B38:B39) -> 0

Sheet SALAIRES CHARGES
A1: MODULE SALAIRES & CHARGES PATRONALES
A2: Bleu = saisir | Noir = calcul auto | Taux modifiables dans onglet PARAMETRES
A4: INTERMITTENTS — GUSO
A5: Nom / Artiste | B5: Rôle | C5: Nb jours | D5: Cachet/jour € | E5: Brut total | F5: Charges GUSO (~40%) | G5: Coût total employeur | H5: ETPT | I5: Statut
E6: =C6*D6 -> 0 | F6: =E6*PARAMETRES!E5 -> 0 | G6: =E6+F6 -> 0 | H6: =IF(C6=0,"-",ROUND(C6/218,3)) -> - | I6: Intermittent GUSO
E7: =C7*D7 -> 0 | F7: =E7*PARAMETRES!E5 -> 0 | G7: =E7+F7 -> 0 | H7: =IF(C7=0,"-",ROUND(C7/218,3)) -> - | I7: Intermittent GUSO
E8: =C8*D8 -> 0 | F8: =E8*PARAMETRES!E5 -> 0 | G8: =E8+F8 -> 0 | H8: =IF(C8=0,"-",ROUND(C8/218,3)) -> - | I8: Intermittent GUSO
E9: =C9*D9 -> 0 | F9: =E9*PARAMETRES!E5 -> 0 | G9: =E9+F9 -> 0 | H9: =IF(C9=0,"-",ROUND(C9/218,3)) -> - | I9: Intermittent GUSO
E10: =C10*D10 -> 0 | F10: =E10*PARAMETRES!E5 -> 0 | G10: =E10+F10 -> 0 | H10: =IF(C10=0,"-",ROUND(C10/218,3)) -> - | I10: Intermittent GUSO
E11: =C11*D11 -> 0 | F11: =E11*PARAMETRES!E5 -> 0 | G11: =E11+F11 -> 0 | H11: =IF(C11=0,"-",ROUND(C11/218,3)) -> - | I11: Intermittent GUSO
E12: =C12*D12 -> 0 | F12: =E12*PARAMETRES!E5 -> 0 | G12: =E12+F12 -> 0 | H12: =IF(C12=0,"-",ROUND(C12/218,3)) -> - | I12: Intermittent GUSO
E13: =C13*D13 -> 0 | F13: =E13*PARAMETRES!E5 -> 0 | G13: =E13+F13 -> 0 | H13: =IF(C13=0,"-",ROUND(C13/218,3)) -> - | I13: Intermittent GUSO
A14: TOTAL GUSO — Brut | E14: =SUM(E6:E13) -> 0 | F14: =SUM(F6:F13) -> 0 | G14: =SUM(G6:G13) -> 0
A16: ARTISTES-AUTEURS — DROITS D'AUTEUR
A17: Nom / Auteur | B17: Type d'œuvre | C17: Nb représent. | D17: Montant HT | E17: Total HT | F17: Contrib. diff. 1,1% | G17: Coût total | H17: Note | I17: Statut
E18: =C18*D18 -> 0 | F18: =E18*PARAMETRES!E8 -> 0 | G18: =E18+F18 -> 0 | H18: Contrat cession/licence | I18: Artiste-auteur
E19: =C19*D19 -> 0 | F19: =E19*PARAMETRES!E8 -> 0 | G19: =E19+F19 -> 0 | H19: Contrat cession/licence | I19: Artiste-auteur
E20: =C20*D20 -> 0 | F20: =E20*PARAMETRES!E8 -> 0 | G20: =E20+F20 -> 0 | H20: Contrat cession/licence | I20: Artiste-auteur
E21: =C21*D21 -> 0 | F21: =E21*PARAMETRES!E8 -> 0 | G21: =E21+F21 -> 0 | H21: Contrat cession/licence | I21: Artiste-auteur
E22: =C22*D22 -> 0 | F22: =E22*PARAMETRES!E8 -> 0 | G22: =E22+F22 -> 0 | H22: Contrat cession/licence | I22: Artiste-auteur
A23: TOTAL ARTISTES-AUTEURS | E23: =SUM(E18:E22) -> 0 | F23: =SUM(F18:F22) -> 0 | G23: =SUM(G18:G22) -> 0
A25: RÉCAPITULATIF GLOBAL
A26: GUSO — Brut total | C26: =E14 -> 0
A27: GUSO — Charges | C27: =F14 -> 0
A28: GUSO — Coût employeur | C28: =G14 -> 0
A29: Artistes-auteurs — HT total | C29: =E23 -> 0
A30: Artistes-auteurs — Contribution diff. | C30: =F23 -> 0
A31: Artistes-auteurs — Coût total | C31: =G23 -> 0
A32: TOTAL COÛT EMPLOYEUR GLOBAL | C32: =G14+G23 -> 0

Sheet ETPT
A1: TABLEAU DES MOYENS HUMAINS — ETPT
A2: ETPT = Nb jours ÷ 218 | 218 jours = référence annuelle conventions collectives spectacle
A4: ETPT — PROJET ARTISTIQUE
A5: Nom / Fonction | B5: Statut | C5: Quotité % | D5: Nb jours projet | E5: Nb heures proj. | F5: ETPT projet | G5: Observations
E6: =IF(D6=0,0,D6*7) -> 0 | F6: =IF(D6=0,"-",ROUND(D6/218,3)) -> -
E7: =IF(D7=0,0,D7*7) -> 0 | F7: =IF(D7=0,"-",ROUND(D7/218,3)) -> -
E8: =IF(D8=0,0,D8*7) -> 0 | F8: =IF(D8=0,"-",ROUND(D8/218,3)) -> -
E9: =IF(D9=0,0,D9*7) -> 0 | F9: =IF(D9=0,"-",ROUND(D9/218,3)) -> -
E10: =IF(D10=0,0,D10*7) -> 0 | F10: =IF(D10=0,"-",ROUND(D10/218,3)) -> -
E11: =IF(D11=0,0,D11*7) -> 0 | F11: =IF(D11=0,"-",ROUND(D11/218,3)) -> -
E12: =IF(D12=0,0,D12*7) -> 0 | F12: =IF(D12=0,"-",ROUND(D12/218,3)) -> -
E13: =IF(D13=0,0,D13*7) -> 0 | F13: =IF(D13=0,"-",ROUND(D13/218,3)) -> -
E14: =IF(D14=0,0,D14*7) -> 0 | F14: =IF(D14=0,"-",ROUND(D14/218,3)) -> -
E15: =IF(D15=0,0,D15*7) -> 0 | F15: =IF(D15=0,"-",ROUND(D15/218,3)) -> -
A16: TOTAL ETPT PROJET | D16: =SUM(D6:D15) -> 0 | F16: =ROUND(D16/218,3) -> 0
A18: ETPT — ASSOCIATION (hors projet)
A19: Nom / Poste | B19: Statut | C19: Quotité % | D19: Nb jours/an | E19: Nb heures/an | F19: ETPT asso | G19: CDI / CDD / Bénévole
E20: =IF(D20=0,0,D20*7) -> 0 | F20: =IF(D20=0,"-",ROUND(D20/218,3)) -> -
E21: =IF(D21=0,0,D21*7) -> 0 | F21: =IF(D21=0,"-",ROUND(D21/218,3)) -> -
E22: =IF(D22=0,0,D22*7) -> 0 | F22: =IF(D22=0,"-",ROUND(D22/218,3)) -> -
E23: =IF(D23=0,0,D23*7) -> 0 | F23: =IF(D23=0,"-",ROUND(D23/218,3)) -> -
E24: =IF(D24=0,0,D24*7) -> 0 | F24: =IF(D24=0,"-",ROUND(D24/218,3)) -> -
E25: =IF(D25=0,0,D25*7) -> 0 | F25: =IF(D25=0,"-",ROUND(D25/218,3)) -> -
E26: =IF(D26=0,0,D26*7) -> 0 | F26: =IF(D26=0,"-",ROUND(D26/218,3)) -> -
E27: =IF(D27=0,0,D27*7) -> 0 | F27: =IF(D27=0,"-",ROUND(D27/218,3)) -> -
A28: TOTAL ETPT ASSOCIATION | D28: =SUM(D20:D27) -> 0 | F28: =SUMIF(F20:F27,"<>-",F20:F27) -> 0
A30: BÉNÉVOLES — Valorisation au SMIC horaire
A31: Nom / Rôle | B31: Mission | C31: Nb heures | D31: Taux SMIC €/h | E31: Valorisation € | F31: ETPT équiv. | G31: Note
D32: =PARAMETRES!E9 -> 11.88 | E32: =IF(C32=0,0,C32*D32) -> 0 | F32: =IF(C32=0,"-",ROUND(C32/1526,3)) -> -
D33: =PARAMETRES!E9 -> 11.88 | E33: =IF(C33=0,0,C33*D33) -> 0 | F33: =IF(C33=0,"-",ROUND(C33/1526,3)) -> -
D34: =PARAMETRES!E9 -> 11.88 | E34: =IF(C34=0,0,C34*D34) -> 0 | F34: =IF(C34=0,"-",ROUND(C34/1526,3)) -> -
D35: =PARAMETRES!E9 -> 11.88 | E35: =IF(C35=0,0,C35*D35) -> 0 | F35: =IF(C35=0,"-",ROUND(C35/1526,3)) -> -
D36: =PARAMETRES!E9 -> 11.88 | E36: =IF(C36=0,0,C36*D36) -> 0 | F36: =IF(C36=0,"-",ROUND(C36/1526,3)) -> -
D37: =PARAMETRES!E9 -> 11.88 | E37: =IF(C37=0,0,C37*D37) -> 0 | F37: =IF(C37=0,"-",ROUND(C37/1526,3)) -> -
A38: TOTAL BÉNÉVOLES VALORISÉS | E38: =SUM(E32:E37) -> 0

Sheet MAIRIE DE PARIS
A1: MATRICE BUDGÉTAIRE — VILLE DE PARIS · Format officiel HHP26S2
A2: Nom de la structure : | B2: =PARAMETRES!B5 -> 0
A3: Nom du projet : | B3: =PARAMETRES!B4 -> 0
A4: ⚠️ Le budget doit être ÉQUILIBRÉ en charges et en produits au niveau des sous-totaux et du total général
A6: CHARGES — NUMÉRAIRE | D6: PRODUITS — NUMÉRAIRE
A7: Artistiques | D7: Ressources propres
A8: Cachets | D8: Autoproduction, réserves
A9: Droits d'auteur | D9: Cession
A10: Autres | D10: Billetterie
A11: Total Artistiques | B11: =SUM(B8:B10) -> 0 | D11: Autres
A12: Technique | D12: Total Ressources propres | E12: =SUM(E8:E11) -> 0
A13: Charges de personnel | D13: Subventions publiques
A14: Prestations de services | D14: Ville de Paris
A15: Autres | D15: DRAC
A16: Total Technique | B16: =SUM(B13:B15) -> 0 | D16: CNM
A17: Matériel et logistique | D17: Région
A18: Prestations de services et locations | D18: Autres
A19: Transport | D19: Total Subventions publiques | E19: =SUM(E14:E18) -> 0
A20: Autres | D20: Financements privés
A21: Total Matériel et logistique | B21: =SUM(B18:B20) -> 0 | D21: Mécénat
A22: Administration | D22: Autres
A23: Charges de personnel | D23: Sociétés de gestion (SACEM…)
A24: Communication | D24: Total Financements privés | E24: =SUM(E21:E23) -> 0
A25: Impôts et taxes, droits divers
A26: Autres
A27: Total Administration | B27: =SUM(B23:B26) -> 0
A28: SOUS-TOTAL NUMÉRAIRE CHARGES | B28: =B11+B16+B21+B27 -> 0 | D28: SOUS-TOTAL NUMÉRAIRE PRODUITS | E28: =E12+E19+E24 -> 0
A30: VALORISATION — Contributions volontaires en nature
A31: Bénévoles | D31: Bénévoles
A32: Apport en nature et industrie | D32: Apport en nature et industrie
A33: Autres | D33: Autres
A34: Sous-total valorisation | B34: =SUM(B31:B33) -> 0 | D34: Sous-total valorisation | E34: =SUM(E31:E33) -> 0
A36: TOTAL GÉNÉRAL CHARGES | B36: =B28+B34 -> 0 | D36: TOTAL GÉNÉRAL PRODUITS | E36: =E28+E34 -> 0
A37: =IF(ABS(B36-E36)>1,"⚠️ NON ÉQUILIBRÉ — écart : "&TEXT(ABS(B36-E36),"#,##0")&" €","✅ Budget équilibré — Total : "&TEXT(B36,"#,##0")&" €") -> ✅ Budget équilibré — Total : 0 €

Sheet BUDGET PARTENAIRES
A1: BUDGET SYNTHÉTIQUE — PARTENAIRES & CO-PRODUCTEURS
A2: Version simplifiée à partager avec les partenaires — sans détail prestataires
A3: Projet : | B3: =PARAMETRES!B4 -> 0
A5: CHARGES | D5: RECETTES
A6: Artistique (cachets, droits, intervenants) | D6: Subventions publiques obtenues
A7: Technique (son, lumière, captation) | D7: Subventions en cours
A8: Communication et promotion | D8: Coproductions confirmées
A9: Administration et coordination | D9: Billetterie prévisionnelle
A10: Déplacements et hébergement | D10: Mécénat et partenariats
A11: Divers et imprévus | D11: Apport structure porteuse
A12: TOTAL CHARGES | B12: =SUM(B6:B11) -> 0 | D12: TOTAL RECETTES | E12: =SUM(E6:E11) -> 0
A14: =IF(ABS(B12-E12)>1,"⚠️ Écart : "&TEXT(ABS(B12-E12),"#,##0")&" €","✅ Budget équilibré") -> ✅ Budget équilibré

Sheet BILAN ASSO
A1: COMPTE DE RÉSULTAT PRÉVISIONNEL — ASSOCIATION LOI 1901
A2: Projet : | B2: =PARAMETRES!B4 -> 0 | D2: Association : | E2: =PARAMETRES!B5 -> 0
A4: CHARGES | D4: PRODUITS
A5: 60 — Achats | D5: 70 — Ventes et prestations
A6: 601 Matières premières | D6: 701 Ventes produits finis
A7: 606 Fournitures | D7: 706 Prestations
A8: 607 Achats marchandises | D8: 707 Marchandises
A9: s/t 60 — Achats | B9: =SUM(B6:B8) -> 0 | D9: s/t 70 — Ventes et prestations | E9: =SUM(E6:E8) -> 0
A10: 61/62 — Services extérieurs | D10: 74 — Subventions exploitation
A11: 611 Sous-traitance | D11: 7411 État
A12: 613 Locations | D12: 7412 Régions
A13: 615 Entretiens et réparations | D13: 7413 Départements
A14: 616 Assurances | D14: 7414 Communes
A15: 617 Documentation | D15: 7415 Établissements publics
A16: 622 Honoraires et intermédiaires | D16: 7417 Organismes sociaux
A17: 623 Publicité | D17: 7418 Autres
A18: 625 Déplacements et missions | D18: s/t 74 — Subventions exploitat | E18: =SUM(E11:E17) -> 0
A19: 626 Frais télécoms | D19: 75 — Autres produits gestion
A20: 628 Autres | D20: 751 Redevances
A21: s/t 61/62 — Services extérieur | B21: =SUM(B11:B20) -> 0 | D21: 754 Cotisations et dons
A22: 63 — Impôts et taxes | D22: 758 Produits divers
A23: 631 Impôts et taxes assimilés | D23: s/t 75 — Autres produits gesti | E23: =SUM(E20:E22) -> 0
A24: s/t 63 — Impôts et taxes | B24: =SUM(B23:B23) -> 0 | D24: 76 — Produits financiers
A25: 64 — Charges de personnel | D25: 764 Revenus valeurs mobilières
A26: 641 Salaires et traitements | D26: 768 Autres
A27: 645 Charges séc. sociale | D27: s/t 76 — Produits financiers | E27: =SUM(E25:E26) -> 0
A28: 647 Autres charges sociales | D28: 77 — Produits exceptionnels
A29: s/t 64 — Charges de personnel | B29: =SUM(B26:B28) -> 0 | D29: 771 Produits except. gestion
A30: 65 — Autres charges | D30: 778 Autres
A31: 654 Pertes sur créances | D31: s/t 77 — Produits exceptionnel | E31: =SUM(E29:E30) -> 0
A32: 658 Charges diverses gestion | D32: 78 — Reprises provisions
A33: s/t 65 — Autres charges | B33: =SUM(B31:B32) -> 0 | D33: 781 Reprises amortissements
A34: 66 — Charges financières | D34: 786 Reprises provisions
A35: 661 Charges d'intérêts | D35: s/t 78 — Reprises provisions | E35: =SUM(E33:E34) -> 0
A36: 668 Autres charges financières | D36: 79 — Transferts de charges
A37: s/t 66 — Charges financières | B37: =SUM(B35:B36) -> 0 | D37: 791 Transferts charges exploitation
A38: 67 — Charges exceptionnelles | D38: s/t 79 — Transferts de charges | E38: =SUM(E37:E37) -> 0
A39: 671 Charges except. gestion
A40: 678 Autres
A41: s/t 67 — Charges exceptionnell | B41: =SUM(B39:B40) -> 0
...
