Workbook

Sheet DASHBOARD
A1: TABLEAU DE BORD ASSOCIATION — Vue synthétique et alertes
A2: Ce dashboard se met à jour automatiquement depuis les onglets. Aucune saisie ici.
A4: Association : | B4: =IDENTITE!B4 -> 0 | C4: SIRET : | D4: =IDENTITE!B6 -> 0 | E4: Responsable : | F4: =IDENTITE!B10 -> 0
A6: ALERTES — Conformité administrative et caisses
A7: Organisme / Document | B7: N° adhérent / identifiant | C7: Date d'expiration / échéance | D7: Statut alerte | E7: Infos à jour ? | F7: Dernière vérif. | G7: Action requise
A8: Licence entrepreneur du spectacle | B8: =IDENTITE!B15 -> 0 | C8: =CAISSES!D5 -> 0 | D8: =IFERROR(IF(C8="","Renseigner date",IF(NOT(ISNUMBER(C8)),"Format invalide",IF(C8<TODAY(),"EXPIRÉ",IF(C8<TODAY()+90,"URGENT < 3 mois",IF(C8<TODAY()+180,"Attention < 6 mois","OK — "&TEXT(C8,"MM/YYYY")))))),"—") -> Renseigner date | E8: Oui
A9: URSSAF — dernier paiement | B9: =CAISSES!C12 -> 0 | C9: =CAISSES!D12 -> 0 | D9: =IFERROR(IF(C9="","Renseigner date",IF(NOT(ISNUMBER(C9)),"Format invalide",IF(C9<TODAY(),"EXPIRÉ",IF(C9<TODAY()+90,"URGENT < 3 mois",IF(C9<TODAY()+180,"Attention < 6 mois","OK — "&TEXT(C9,"MM/YYYY")))))),"—") -> Renseigner date | E9: Oui
A10: GUSO — compte actif | B10: =CAISSES!C17 -> 0 | C10: =CAISSES!D17 -> 0 | D10: =IFERROR(IF(C10="","Renseigner date",IF(NOT(ISNUMBER(C10)),"Format invalide",IF(C10<TODAY(),"EXPIRÉ",IF(C10<TODAY()+90,"URGENT < 3 mois",IF(C10<TODAY()+180,"Attention < 6 mois","OK — "&TEXT(C10,"MM/YYYY")))))),"—") -> Renseigner date | E10: Oui
A11: Audiens — affiliation | B11: =CAISSES!C22 -> 0 | C11: =CAISSES!D22 -> 0 | D11: =IFERROR(IF(C11="","Renseigner date",IF(NOT(ISNUMBER(C11)),"Format invalide",IF(C11<TODAY(),"EXPIRÉ",IF(C11<TODAY()+90,"URGENT < 3 mois",IF(C11<TODAY()+180,"Attention < 6 mois","OK — "&TEXT(C11,"MM/YYYY")))))),"—") -> Renseigner date | E11: Oui
A12: AFDAS — adhésion | B12: =CAISSES!C27 -> 0 | C12: =CAISSES!D27 -> 0 | D12: =IFERROR(IF(C12="","Renseigner date",IF(NOT(ISNUMBER(C12)),"Format invalide",IF(C12<TODAY(),"EXPIRÉ",IF(C12<TODAY()+90,"URGENT < 3 mois",IF(C12<TODAY()+180,"Attention < 6 mois","OK — "&TEXT(C12,"MM/YYYY")))))),"—") -> Renseigner date | E12: Oui
A13: Congés Spectacles — adhésion | B13: =CAISSES!C32 -> 0 | C13: =CAISSES!D32 -> 0 | D13: =IFERROR(IF(C13="","Renseigner date",IF(NOT(ISNUMBER(C13)),"Format invalide",IF(C13<TODAY(),"EXPIRÉ",IF(C13<TODAY()+90,"URGENT < 3 mois",IF(C13<TODAY()+180,"Attention < 6 mois","OK — "&TEXT(C13,"MM/YYYY")))))),"—") -> Renseigner date | E13: Oui
A14: Mutuelle obligatoire | B14: =CAISSES!C37 -> 0 | C14: =CAISSES!D37 -> 0 | D14: =IFERROR(IF(C14="","Renseigner date",IF(NOT(ISNUMBER(C14)),"Format invalide",IF(C14<TODAY(),"EXPIRÉ",IF(C14<TODAY()+90,"URGENT < 3 mois",IF(C14<TODAY()+180,"Attention < 6 mois","OK — "&TEXT(C14,"MM/YYYY")))))),"—") -> Renseigner date | E14: Oui
A15: Pôle Emploi Spectacle — compte | B15: =CAISSES!C42 -> Valeur enregistrée chez caisses | C15: =CAISSES!D42 -> Cohérent ? | D15: =IFERROR(IF(C15="","Renseigner date",IF(NOT(ISNUMBER(C15)),"Format invalide",IF(C15<TODAY(),"EXPIRÉ",IF(C15<TODAY()+90,"URGENT < 3 mois",IF(C15<TODAY()+180,"Attention < 6 mois","OK — "&TEXT(C15,"MM/YYYY")))))),"—") -> Format invalide | E15: Oui
A17: SYNTHÈSE MOYENS HUMAINS — N-1 / N / N+1
A18: Indicateur | B18: N-1 (réalisé) | C18: N (en cours) | D18: N+1 (projeté) | E18: Évolution N-1→N | F18: Évolution N→N+1 | G18: Note
A19: ETP permanents (CDI/CDD) | B19: =RH_ASSO!C48 -> 0 | C19: =RH_ASSO!D48 -> 0 | D19: =RH_ASSO!E48 -> 0 | E19: =IF(B19=0,"-",C19/B19-1) -> - | F19: =IF(C19=0,"-",D19/C19-1) -> -
A20: ETP bénévoles valorisés | B20: =RH_ASSO!C60 -> 0 | C20: =RH_ASSO!D60 -> 0 | D20: =RH_ASSO!E60 -> 0 | E20: =IF(B20=0,"-",C20/B20-1) -> - | F20: =IF(C20=0,"-",D20/C20-1) -> -
A21: Masse salariale brute (€) | B21: =RH_ASSO!C70 -> 0 | C21: =RH_ASSO!D70 -> 0 | D21: =RH_ASSO!E70 -> 0 | E21: =IF(B21=0,"-",C21/B21-1) -> - | F21: =IF(C21=0,"-",D21/C21-1) -> -
A22: Charges patronales (€) | B22: =RH_ASSO!C71 -> 0 | C22: =RH_ASSO!D71 -> 0 | D22: =RH_ASSO!E71 -> 0 | E22: =IF(B22=0,"-",C22/B22-1) -> - | F22: =IF(C22=0,"-",D22/C22-1) -> -
A23: Coût total employeur (€) | B23: =RH_ASSO!C72 -> 0 | C23: =RH_ASSO!D72 -> 0 | D23: =RH_ASSO!E72 -> 0 | E23: =IF(B23=0,"-",C23/B23-1) -> - | F23: =IF(C23=0,"-",D23/C23-1) -> -
A25: SYNTHÈSE FINANCIÈRE ASSOCIATION — N-1 / N / N+1
A26: Indicateur | B26: N-1 (réalisé) | C26: N (prévisionnel) | D26: N+1 (projeté) | E26: Source | F26: Date MAJ | G26: Note
A27: Total produits asso | B27: =FINANCES!C10 -> 0 | C27: =FINANCES!D10 -> 0 | D27: =FINANCES!E10 -> 0
A28: Total charges asso | B28: =FINANCES!C30 -> 0 | C28: =FINANCES!D30 -> 0 | D28: =FINANCES!E30 -> 0
A29: Résultat net | B29: =FINANCES!C32 -> 0 | C29: =FINANCES!D32 -> 0 | D29: =FINANCES!E32 -> 0
A30: Fonds propres / réserves | B30: =FINANCES!C35 -> 0 | C30: =FINANCES!D35 -> 0 | D30: =FINANCES!E35 -> 0
A31: Trésorerie disponible | B31: =FINANCES!C36 -> 0 | C31: =FINANCES!D36 -> 0 | D31: =FINANCES!E36 -> 0

Sheet IDENTITE
A1: IDENTITÉ ASSOCIATION — Informations de référence
A2: Toutes les informations ici alimentent automatiquement les autres onglets et les dossiers projets
A4: INFORMATIONS GÉNÉRALES | D4: AGRÉMENTS & LICENCES
A5: Nom officiel de l'association | D5: Document / agrément | E5: Numéro / détail
A6: Nom usuel / commercial | D6: Licence entrepreneur du spectacle — Type 1 (prod.)
A7: SIRET | D7: Licence entrepreneur du spectacle — Type 2 (prod.)
A8: Code APE / NAF | D8: Licence entrepreneur du spectacle — Type 3 (diff.)
A9: N° RNA | D9: Convention collective applicable | E9: CCN Spectacle vivant privé / CCN CCNEAC
A10: Date de création | D10: Code APE — Arts du spectacle
A11: Date de dernière AG | D11: Agrément jeunesse et éducation populaire
A12: Adresse du siège social | D12: Agrément formation professionnelle (QUALIOPI)
A13: Adresse de correspondance (si diff.)
D14: DATES D'EXPIRATION À SURVEILLER
A15: DIRECTION ET CONTACTS | D15: Document | E15: Date d'expiration
A16: Président(e) | D16: Licence spectacle Type 1
A17: Trésorier(e) | D17: Licence spectacle Type 2
A18: Secrétaire | D18: Licence spectacle Type 3
A19: Directeur(rice) artistique | D19: Agrément JEP
A20: Administrateur(rice) de production | D20: QUALIOPI
A21: Email de contact principal | D21: Contrat assurance RC pro
A22: Téléphone principal | D22: Contrat mutuelle obligatoire
A23: Site internet
A24: Réseaux sociaux principaux
A25: COMPTES BANCAIRES
A26: Banque | B26: IBAN | C26: BIC | D26: Usage | E26: Date ouverture
A27: Compte principal | D27: Opérations courantes
A28: Compte épargne / réserve | D28: Fonds propres
A29: Autre

Sheet CAISSES
A1: CAISSES & ORGANISMES SOCIAUX — Conformité et alertes
A2: Renseigner chaque caisse. Les alertes se déclenchent automatiquement à 6 mois et 3 mois avant échéance.
A4: Organisme | B4: Caisse ouverte ? | C4: N° adhérent / identifiant | D4: Date expiration / échéance | E4: Infos à jour ? | F4: Dernière vérification | G4: Alerte automatique | H4: Contact / interlocuteur
A5: URSSAF — Cotisations sociales
A6: Numéro URSSAF (compte cotisant) | B6: Oui | E6: Oui | G6: =IF(D6="","—",IF(D6<TODAY(),"EXPIRÉ",IF(D6<TODAY()+90,"URGENT < 3 mois",IF(D6<TODAY()+180,"Attention < 6 mois","OK — "&TEXT(D6,"MM/YYYY"))))) -> —
A7: Déclaration et paiement mensuel / trimestriel | B7: Oui | E7: Oui | G7: =IF(D7="","—",IF(D7<TODAY(),"EXPIRÉ",IF(D7<TODAY()+90,"URGENT < 3 mois",IF(D7<TODAY()+180,"Attention < 6 mois","OK — "&TEXT(D7,"MM/YYYY"))))) -> —
A8: Mise à jour adresse et représentant légal | B8: Oui | E8: Oui | G8: =IF(D8="","—",IF(D8<TODAY(),"EXPIRÉ",IF(D8<TODAY()+90,"URGENT < 3 mois",IF(D8<TODAY()+180,"Attention < 6 mois","OK — "&TEXT(D8,"MM/YYYY"))))) -> —
A9: GUSO — Guichet Unique du Spectacle Occasionnel
A10: Compte GUSO actif (pour intermittents occasionnels) | B10: Oui | E10: Oui | G10: =IF(D10="","—",IF(D10<TODAY(),"EXPIRÉ",IF(D10<TODAY()+90,"URGENT < 3 mois",IF(D10<TODAY()+180,"Attention < 6 mois","OK — "&TEXT(D10,"MM/YYYY"))))) -> —
A11: Identifiant employeur GUSO | B11: Oui | E11: Oui | G11: =IF(D11="","—",IF(D11<TODAY(),"EXPIRÉ",IF(D11<TODAY()+90,"URGENT < 3 mois",IF(D11<TODAY()+180,"Attention < 6 mois","OK — "&TEXT(D11,"MM/YYYY"))))) -> —
A12: Mise à jour informations structure | B12: Oui | E12: Oui | G12: =IF(D12="","—",IF(D12<TODAY(),"EXPIRÉ",IF(D12<TODAY()+90,"URGENT < 3 mois",IF(D12<TODAY()+180,"Attention < 6 mois","OK — "&TEXT(D12,"MM/YYYY"))))) -> —
A13: AUDIENS — Retraite complémentaire spectacle
A14: Numéro adhérent Audiens | B14: Oui | E14: Oui | G14: =IF(D14="","—",IF(D14<TODAY(),"EXPIRÉ",IF(D14<TODAY()+90,"URGENT < 3 mois",IF(D14<TODAY()+180,"Attention < 6 mois","OK — "&TEXT(D14,"MM/YYYY"))))) -> —
A15: Affiliation retraite complémentaire AGIRC-ARRCO | B15: Oui | E15: Oui | G15: =IF(D15="","—",IF(D15<TODAY(),"EXPIRÉ",IF(D15<TODAY()+90,"URGENT < 3 mois",IF(D15<TODAY()+180,"Attention < 6 mois","OK — "&TEXT(D15,"MM/YYYY"))))) -> —
A16: Prévoyance (si applicable) | B16: Oui | E16: Oui | G16: =IF(D16="","—",IF(D16<TODAY(),"EXPIRÉ",IF(D16<TODAY()+90,"URGENT < 3 mois",IF(D16<TODAY()+180,"Attention < 6 mois","OK — "&TEXT(D16,"MM/YYYY"))))) -> —
A17: Mise à jour informations | B17: Oui | E17: Oui | G17: =IF(D17="","—",IF(D17<TODAY(),"EXPIRÉ",IF(D17<TODAY()+90,"URGENT < 3 mois",IF(D17<TODAY()+180,"Attention < 6 mois","OK — "&TEXT(D17,"MM/YYYY"))))) -> —
A18: AFDAS — Formation professionnelle (OPCO spectacle)
A19: Numéro adhérent AFDAS | B19: Oui | E19: Oui | G19: =IF(D19="","—",IF(D19<TODAY(),"EXPIRÉ",IF(D19<TODAY()+90,"URGENT < 3 mois",IF(D19<TODAY()+180,"Attention < 6 mois","OK — "&TEXT(D19,"MM/YYYY"))))) -> —
A20: Plan de formation annuel déposé | B20: Oui | E20: Oui | G20: =IF(D20="","—",IF(D20<TODAY(),"EXPIRÉ",IF(D20<TODAY()+90,"URGENT < 3 mois",IF(D20<TODAY()+180,"Attention < 6 mois","OK — "&TEXT(D20,"MM/YYYY"))))) -> —
A21: Mise à jour informations employeur | B21: Oui | E21: Oui | G21: =IF(D21="","—",IF(D21<TODAY(),"EXPIRÉ",IF(D21<TODAY()+90,"URGENT < 3 mois",IF(D21<TODAY()+180,"Attention < 6 mois","OK — "&TEXT(D21,"MM/YYYY"))))) -> —
A22: CONGÉS SPECTACLES — Caisse des congés payés
A23: Numéro adhérent Congés Spectacles | B23: Oui | E23: Oui | G23: =IF(D23="","—",IF(D23<TODAY(),"EXPIRÉ",IF(D23<TODAY()+90,"URGENT < 3 mois",IF(D23<TODAY()+180,"Attention < 6 mois","OK — "&TEXT(D23,"MM/YYYY"))))) -> —
A24: Déclaration trimestrielle à jour | B24: Oui | E24: Oui | G24: =IF(D24="","—",IF(D24<TODAY(),"EXPIRÉ",IF(D24<TODAY()+90,"URGENT < 3 mois",IF(D24<TODAY()+180,"Attention < 6 mois","OK — "&TEXT(D24,"MM/YYYY"))))) -> —
A25: Mise à jour informations | B25: Oui | E25: Oui | G25: =IF(D25="","—",IF(D25<TODAY(),"EXPIRÉ",IF(D25<TODAY()+90,"URGENT < 3 mois",IF(D25<TODAY()+180,"Attention < 6 mois","OK — "&TEXT(D25,"MM/YYYY"))))) -> —
A26: PÔLE EMPLOI SPECTACLE / FRANCE TRAVAIL
A27: Numéro SIRET déclaré | B27: Oui | E27: Oui | G27: =IF(D27="","—",IF(D27<TODAY(),"EXPIRÉ",IF(D27<TODAY()+90,"URGENT < 3 mois",IF(D27<TODAY()+180,"Attention < 6 mois","OK — "&TEXT(D27,"MM/YYYY"))))) -> —
A28: Compte employeur France Travail | B28: Oui | E28: Oui | G28: =IF(D28="","—",IF(D28<TODAY(),"EXPIRÉ",IF(D28<TODAY()+90,"URGENT < 3 mois",IF(D28<TODAY()+180,"Attention < 6 mois","OK — "&TEXT(D28,"MM/YYYY"))))) -> —
A29: Attestations employeur (AEM) à jour | B29: Oui | E29: Oui | G29: =IF(D29="","—",IF(D29<TODAY(),"EXPIRÉ",IF(D29<TODAY()+90,"URGENT < 3 mois",IF(D29<TODAY()+180,"Attention < 6 mois","OK — "&TEXT(D29,"MM/YYYY"))))) -> —
A30: SACEM / SPEDIDAM / ADAMI — Droits
A31: Compte SACEM (diffusion musicale) | B31: Oui | E31: Oui | G31: =IF(D31="","—",IF(D31<TODAY(),"EXPIRÉ",IF(D31<TODAY()+90,"URGENT < 3 mois",IF(D31<TODAY()+180,"Attention < 6 mois","OK — "&TEXT(D31,"MM/YYYY"))))) -> —
A32: Compte SPEDIDAM (interprètes) | B32: Oui | E32: Oui | G32: =IF(D32="","—",IF(D32<TODAY(),"EXPIRÉ",IF(D32<TODAY()+90,"URGENT < 3 mois",IF(D32<TODAY()+180,"Attention < 6 mois","OK — "&TEXT(D32,"MM/YYYY"))))) -> —
A33: Compte ADAMI (artistes interprètes) | B33: Oui | E33: Oui | G33: =IF(D33="","—",IF(D33<TODAY(),"EXPIRÉ",IF(D33<TODAY()+90,"URGENT < 3 mois",IF(D33<TODAY()+180,"Attention < 6 mois","OK — "&TEXT(D33,"MM/YYYY"))))) -> —
A34: Mise à jour informations | B34: Oui | E34: Oui | G34: =IF(D34="","—",IF(D34<TODAY(),"EXPIRÉ",IF(D34<TODAY()+90,"URGENT < 3 mois",IF(D34<TODAY()+180,"Attention < 6 mois","OK — "&TEXT(D34,"MM/YYYY"))))) -> —
A35: MUTUELLE OBLIGATOIRE
A36: Contrat mutuelle collective | B36: Oui | E36: Oui | G36: =IF(D36="","—",IF(D36<TODAY(),"EXPIRÉ",IF(D36<TODAY()+90,"URGENT < 3 mois",IF(D36<TODAY()+180,"Attention < 6 mois","OK — "&TEXT(D36,"MM/YYYY"))))) -> —
A37: Date d'expiration / renouvellement | B37: Oui | E37: Oui | G37: =IF(D37="","—",IF(D37<TODAY(),"EXPIRÉ",IF(D37<TODAY()+90,"URGENT < 3 mois",IF(D37<TODAY()+180,"Attention < 6 mois","OK — "&TEXT(D37,"MM/YYYY"))))) -> —
A38: Couverture minimale (100% base sécu) | B38: Oui | E38: Oui | G38: =IF(D38="","—",IF(D38<TODAY(),"EXPIRÉ",IF(D38<TODAY()+90,"URGENT < 3 mois",IF(D38<TODAY()+180,"Attention < 6 mois","OK — "&TEXT(D38,"MM/YYYY"))))) -> —
A40: INFORMATIONS À SYNCHRONISER AVEC TOUTES LES CAISSES
A41: Ces informations doivent être identiques chez tous les organismes. Toute modification doit être déclarée dans les 30 jours.
A42: Information | B42: Valeur actuelle | C42: Valeur enregistrée chez caisses | D42: Cohérent ? | E42: Date dernière MAJ | F42: Action requise
...

Sheet RH_ASSO
A1: MOYENS HUMAINS ASSOCIATION — N-1 / N / N+1
A2: N-1 = exercice réalisé | N = exercice en cours | N+1 = projection | ETPT = Équivalent Temps Plein Travaillé
C3: Année N-1 | D3: Année N | E3: Année N+1
A4: Poste / Fonction | B4: Statut | C4: N-1 ETPT | D4: N ETPT | E4: N+1 ETPT | F4: Quotité N | G4: Observations
A5: SALARIÉS PERMANENTS (CDI / CDD longue durée)
A6: Directeur(rice) artistique | B6: CDI
A7: Administrateur(rice) de production | B7: CDI
A8: Chargé(e) de production | B8: CDI
A9: Chargé(e) de communication | B9: CDI
A10: Chargé(e) de médiation culturelle | B10: CDI
A11: Comptable / assistant(e) de gestion | B11: CDI
A12: Autre permanent(e) 1 | B12: CDI
A13: Autre permanent(e) 2 | B13: CDI
A14: SOUS-TOTAL ETPT PERMANENTS | C14: =SUM(C6:C13) -> 0 | D14: =SUM(D6:D13) -> 0 | E14: =SUM(E6:E13) -> 0
A16: CDD COURTS ET INTERMITTENTS RÉGULIERS DE L'ASSO (hors projets)
A17: Intervenant(e) régulier — ateliers | B17: Intermittent
A18: Technicien(ne) régulier(e) | B18: Intermittent
A19: Assistant(e) de production ponctuel(le) | B19: Intermittent
A20: Autre intermittent régulier | B20: Intermittent
A21: SOUS-TOTAL ETPT INTERMITTENTS ASSO | C21: =SUM(C17:C20) -> 0 | D21: =SUM(D17:D20) -> 0 | E21: =SUM(E17:E20) -> 0
A23: BÉNÉVOLES RÉGULIERS — Valorisation
A24: Rôle bénévole | B24: Mission principale | C24: Nb heures/an N-1 | D24: Nb heures/an N | E24: Nb heures/an N+1 | F24: Valeur SMIC (N) | G24: Observations
A25: Président(e) bénévole | F25: =IF(D25=0,0,D25*11.88) -> 0
A26: Trésorier(e) bénévole | F26: =IF(D26=0,0,D26*11.88) -> 0
A27: Secrétaire bénévole | F27: =IF(D27=0,0,D27*11.88) -> 0
A28: Bénévole opérationnel(le) 1 | F28: =IF(D28=0,0,D28*11.88) -> 0
A29: Bénévole opérationnel(le) 2 | F29: =IF(D29=0,0,D29*11.88) -> 0
A30: Autre bénévole | F30: =IF(D30=0,0,D30*11.88) -> 0
A31: SOUS-TOTAL BÉNÉVOLES VALORISÉS | C31: =SUM(C25:C30) -> 0 | D31: =SUM(D25:D30) -> 0 | E31: =SUM(E25:E30) -> 0 | F31: =SUM(F25:F30) -> 0
A33: RÉCAPITULATIF MASSE SALARIALE — N-1 / N / N+1
A34: Poste | C34: N-1 | D34: N | E34: N+1 | F34: Taux charges | G34: Note
A35: ETPT total permanents | C35: =C14 -> 0 | D35: =D14 -> 0 | E35: =E14 -> 0 | F35: —
A36: ETPT total intermittents asso | C36: =C21 -> 0 | D36: =D21 -> 0 | E36: =E21 -> 0 | F36: —
A37: Total ETPT salarié asso | C37: =C35+C36 -> 0 | D37: =D35+D36 -> 0 | E37: =E35+E36 -> 0 | F37: —
A39: Masse salariale brute estimée (N)
A40: Charges patronales estimées (N) | D40: =D39*0.43 -> 0
A41: COÛT TOTAL EMPLOYEUR (N) | D41: =D39+D40 -> 0

Sheet FINANCES
A1: FINANCES ASSOCIATION — Compte de résultat N-1 / N / N+1
A2: N-1 = bilan certifié | N = prévisionnel en cours | N+1 = projection
A4: PRODUITS | C4: N-1 réalisé | D4: N prévisionnel | E4: N+1 projection | F4: Note / source
A5: 70 Ventes et prestations
A6: 701 Ventes produits finis
A7: 706 Prestations de services
A8: 74 Subventions d'exploitation
A9: 7411 État / ministères
A10: 7412 Régions
A11: 7413 Départements
A12: 7414 Communes
A13: 7415 Établissements publics
A14: 7417 Organismes sociaux
A15: 7418 Autres organismes
A16: 75 Autres produits de gestion
... A18: 758 Produits divers
A19: TOTAL PRODUITS | C19: =C6+C7+C9+C10+C11+C12+C13+C14+C15+C17+C18 -> 0 | D19: =D6+D7+D9+D10+D11+D12+D13+D14+D15+D17+D18 -> 0 | E19: =E6+E7+E9+E10+E11+E12+E13+E14+E15+E17+E18 -> 0
A21: CHARGES | C21: N-1 réalisé | D21: N prévisionnel | E21: N+1 projection | F21: Note / source
A22: 60 Achats
A23: 601/606 Fournitures et achats
A24: 61-62 Services extérieurs
A25: 613 Locations
A26: 616 Assurances
A27: 622 Honoraires et rémunérations
A28: 623 Communication
A29: 625 Déplacements
A30: 628 Autres services
A31: 64 Charges de personnel
A32: 641 Salaires bruts
A33: 645 Charges sociales patronales
... A38: 681 Dotations aux amortissements
A39: TOTAL CHARGES | C39: =C23+C25+C26+C27+C28+C29+C30+C32+C33+C35+C36+C38 -> 0 | D39: =D23+D25+D26+D27+D28+D29+D30+D32+D33+D35+D36+D38 -> 0 | E39: =E23+E25+E26+E27+E28+E29+E30+E32+E33+E35+E36+E38 -> 0
A41: RÉSULTAT NET | C41: =C19-C39 -> 0 | D41: =D19-D39 -> 0 | E41: =E19-E39 -> 0
A43: BILAN SIMPLIFIÉ ET TRÉSORERIE
A44: Fonds propres (capital + réserves) | B44: Actif net
A45: Report à nouveau | B45: Résultat N-1 non affecté
A46: Trésorerie disponible | B46: Solde bancaire
A47: Dettes et obligations | B47: Emprunts + charges à payer

Sheet COLLECTE_DOCS
A1: MODÈLE DE COLLECTE DOCUMENTS — À remettre au client
A2: Ce document liste toutes les informations et pièces à fournir. Cocher 'Reçu' au fur et à mesure.
A4: Document / Information | B4: Priorité | C4: Format attendu | D4: Reçu ? | E4: Date réception | F4: Pourquoi nécessaire
A5: PIÈCES ADMINISTRATIVES OBLIGATOIRES
A6: Statuts de l'association à jour | B6: Obligatoire | C6: PDF | D6: Non | F6: Dossier subvention
A7: Récépissé de déclaration en préfecture | B7: Obligatoire | C7: PDF | D7: Non | F7: Preuve d'existence
A8: PV du dernier CA approuvant les comptes | B8: Obligatoire | C8: PDF | D8: Non | F8: Dossier subvention
A9: PV de la dernière AG | B9: Obligatoire | C9: PDF | D9: Non | F9: Dossier subvention
A10: Liste des membres du bureau (nom + fonction) | B10: Obligatoire | C10: PDF/Word | D10: Non | F10: Dossier subvention
A11: Relevé d'identité bancaire (RIB) asso | B11: Obligatoire | C11: PDF | D11: Non | F11: Versement subventions
A12: Extrait Kbis ou récépissé RNA | B12: Obligatoire | C12: PDF | D12: Non | F12: Dossier administratif
A13: LICENCES ET AGRÉMENTS
A14: Licence entrepreneur du spectacle (type 1, 2 ou 3) | B14: Obligatoire | C14: PDF | D14: Non | F14: Condition légale
A15: Attestation en cours de renouvellement si expirée | B15: Si applicable | C15: PDF | D15: Non | F15: Dossier subvention
A16: Agrément JEP (si applicable) | B16: Si applicable | C16: PDF | D16: Non | F16: Actions éducatives
A17: PIÈCES COMPTABLES ET FINANCIÈRES
A18: Bilan comptable N-1 (exercice précédent) | B18: Obligatoire | C18: PDF/Excel | D18: Non | F18: Faisabilité financière
A19: Compte de résultat N-1 | B19: Obligatoire | C19: PDF/Excel | D19: Non | F19: Faisabilité financière
A20: Bilan comptable N-2 (si disponible) | B20: Fortement recommandé | C20: PDF/Excel | D20: Non | F20: Crédibilité dossier
A21: Budget prévisionnel N (exercice en cours) | B21: Obligatoire | C21: Excel | D21: Non | F21: Dossier subvention
A22: Situation de trésorerie récente | B22: Recommandé | C22: PDF/Excel | D22: Non | F22: Faisabilité immédiate
A23: Attestation de régularité fiscale et sociale | B23: Obligatoire si >3000€ | C23: PDF | D23: Non | F23: Dossier Mairie Paris
A24: INFORMATIONS ORGANISMES SOCIAUX
A25: N° URSSAF et attestation de régularité | B25: Obligatoire si salariés | C25: PDF | D25: Non | F25: Conformité sociale
A26: N° GUSO (si intermittents occasionnels) | B26: Si applicable | C26: Identifiant | D26: Non | F26: Paiement artistes
A27: N° Audiens (si salariés permanents) | B27: Si applicable | C27: Identifiant | D27: Non | F27: Retraite compl.
A28: N° AFDAS (si salariés) | B28: Si applicable | C28: Identifiant | D28: Non | F28: Formation pro
A29: N° Congés Spectacles | B29: Si applicable | C29: Identifiant | D29: Non | F29: Congés payés
A30: Contrat mutuelle obligatoire | B30: Si salariés | C30: PDF | D30: Non | F30: Obligation légale
A31: Convention collective applicable | B31: Obligatoire | C31: Référence | D31: Non | F31: Cadre social
A32: INFORMATIONS PROJET (EN PLUS DE L'ASSO)
A33: Note artistique et descriptif du projet | B33: Obligatoire | C33: PDF | D33: Non | F33: Dossier artistique
A34: Programmation prévisionnelle détaillée | B34: Obligatoire | C34: PDF | D34: Non | F34: Dossier subvention
A35: Liste des artistes avec statuts et cachets | B35: Obligatoire | C35: Excel | D35: Non | F35: Budget artistes
A36: Lettre d'engagement ou contrat lieu | B36: Obligatoire | C36: PDF | D36: Non | F36: Dossier Mairie Paris
A37: Preuves des demandes de subvention en cours | B37: Si disponibles | C37: PDF | D37: Non | F37: Crédibilité plan financement
A38: Contrats cession droits (films, photos…) | B38: Si applicable | C38: PDF | D38: Non | F38: Prévention contentieux
A39: Devis prestataires principaux | B39: Recommandé | C39: PDF | D39: Non | F39: Budget prévisionnel
A41: ="Complétion : "&COUNTIF(D5:D40,"Oui")&" / "&COUNTA(D5:D40)&" documents reçus ("&TEXT(COUNTIF(D5:D40,"Oui")/COUNTA(D5:D40),"0%")&")" -> Complétion : 0 / 30 documents reçus (0%)
