Workbook

Sheet DASHBOARD
A1: TABLEAU DE BORD — SAS SÉNÉGALAISE — Vue synthétique et alertes
A2: Fichier adapté pour une SAS régie par le droit OHADA (Acte Uniforme sociétés commerciales). Monnaie : FCFA. Organismes sociaux : IPRES + CSS.
A3: ⚡ DIFFÉRENCES CLÉS vs ASSOCIATION LOI 1901 : Forme juridique SAS OHADA | Monnaie FCFA | Organismes IPRES/CSS | IS 30% | TVA 18% | SYSCOA/OHADA comptabilité
A5: Société : | B5: =IDENTITE!B4 -> 0 | C5: NINEA : | D5: =IDENTITE!B6 -> 0 | E5: N° RCCM : | F5: =IDENTITE!B7 -> SAS — Société par Actions Simplifiée (OHADA) | G5: Représentant légal : | H5: =IDENTITE!B10 -> 0
A7: ALERTES — Conformité administrative et organismes sociaux
A8: Organisme / Document | B8: N° adhérent / identifiant | C8: Date expiration / échéance | D8: Statut alerte | E8: Infos à jour ? | F8: Dernière vérif. | G8: Action requise
A9: Patente (contribution économique locale) | B9: =ORGANISMES!C6 -> 0 | C9: =ORGANISMES!D6 -> 0 | D9: =IFERROR(IF(C9="","Renseigner",IF(NOT(ISNUMBER(C9)),"Format invalide",IF(C9<TODAY(),"EXPIRÉ",IF(C9<TODAY()+90,"URGENT < 3 mois",IF(C9<TODAY()+180,"Attention < 6 mois","OK"))))),"-") -> Renseigner | E9: Oui
A10: NINEA — validité et mise à jour | B10: =ORGANISMES!C11 -> 0 | C10: =ORGANISMES!D11 -> 0 | D10: =IFERROR(IF(C10="","Renseigner",IF(NOT(ISNUMBER(C10)),"Format invalide",IF(C10<TODAY(),"EXPIRÉ",IF(C10<TODAY()+90,"URGENT < 3 mois",IF(C10<TODAY()+180,"Attention < 6 mois","OK"))))),"-") -> Renseigner | E10: Oui
A11: IPRES — retraite de base (RG) | B11: =ORGANISMES!C16 -> 0 | C11: =ORGANISMES!D16 -> 0 | D11: =IFERROR(IF(C11="","Renseigner",IF(NOT(ISNUMBER(C11)),"Format invalide",IF(C11<TODAY(),"EXPIRÉ",IF(C11<TODAY()+90,"URGENT < 3 mois",IF(C11<TODAY()+180,"Attention < 6 mois","OK"))))),"-") -> Renseigner | E11: Oui
A12: IPRES — retraite complémentaire (RC) | B12: =ORGANISMES!C21 -> 0 | C12: =ORGANISMES!D21 -> 0 | D12: =IFERROR(IF(C12="","Renseigner",IF(NOT(ISNUMBER(C12)),"Format invalide",IF(C12<TODAY(),"EXPIRÉ",IF(C12<TODAY()+90,"URGENT < 3 mois",IF(C12<TODAY()+180,"Attention < 6 mois","OK"))))),"-") -> Renseigner | E12: Oui
A13: CSS — Caisse Sécurité Sociale | B13: =ORGANISMES!C26 -> 0 | C13: =ORGANISMES!D26 -> 0 | D13: =IFERROR(IF(C13="","Renseigner",IF(NOT(ISNUMBER(C13)),"Format invalide",IF(C13<TODAY(),"EXPIRÉ",IF(C13<TODAY()+90,"URGENT < 3 mois",IF(C13<TODAY()+180,"Attention < 6 mois","OK"))))),"-") -> Renseigner | E13: Oui
A14: IPM — Mutuelle maladie | B14: =ORGANISMES!C31 -> 0 | C14: =ORGANISMES!D31 -> 0 | D14: =IFERROR(IF(C14="","Renseigner",IF(NOT(ISNUMBER(C14)),"Format invalide",IF(C14<TODAY(),"EXPIRÉ",IF(C14<TODAY()+90,"URGENT < 3 mois",IF(C14<TODAY()+180,"Attention < 6 mois","OK"))))),"-") -> Renseigner | E14: Oui
A15: Inspection du Travail — Déclaration établissement | B15: =ORGANISMES!C36 -> 0 | C15: =ORGANISMES!D36 -> 0 | D15: =IFERROR(IF(C15="","Renseigner",IF(NOT(ISNUMBER(C15)),"Format invalide",IF(C15<TODAY(),"EXPIRÉ",IF(C15<TODAY()+90,"URGENT < 3 mois",IF(C15<TODAY()+180,"Attention < 6 mois","OK"))))),"-") -> Renseigner | E15: Oui
A16: RCCM — mise à jour registre commerce | B16: =ORGANISMES!C41 -> 0 | C16: =ORGANISMES!D41 -> 0 | D16: =IFERROR(IF(C16="","Renseigner",IF(NOT(ISNUMBER(C16)),"Format invalide",IF(C16<TODAY(),"EXPIRÉ",IF(C16<TODAY()+90,"URGENT < 3 mois",IF(C16<TODAY()+180,"Attention < 6 mois","OK"))))),"-") -> Renseigner | E16: Oui
A17: IS — Impôt sur les Sociétés (déclaration annuelle) | B17: =ORGANISMES!C46 -> 0 | C17: =ORGANISMES!D46 -> ? | D17: =IFERROR(IF(C17="","Renseigner",IF(NOT(ISNUMBER(C17)),"Format invalide",IF(C17<TODAY(),"EXPIRÉ",IF(C17<TODAY()+90,"URGENT < 3 mois",IF(C17<TODAY()+180,"Attention < 6 mois","OK"))))),"-") -> Format invalide | E17: Oui
A18: TVA — déclaration mensuelle | B18: =ORGANISMES!C51 -> 0 | C18: =ORGANISMES!D51 -> 0 | D18: =IFERROR(IF(C18="","Renseigner",IF(NOT(ISNUMBER(C18)),"Format invalide",IF(C18<TODAY(),"EXPIRÉ",IF(C18<TODAY()+90,"URGENT < 3 mois",IF(C18<TODAY()+180,"Attention < 6 mois","OK"))))),"-") -> Renseigner | E18: Oui
A20: SYNTHÈSE MOYENS HUMAINS — N-1 / N / N+1 (en FCFA)
A21: Indicateur | B21: N-1 réalisé | C21: N en cours | D21: N+1 projeté | E21: Évol. N-1→N | F21: Évol. N→N+1 | G21: Note
A22: ETP permanents | B22: =RH_SAS!C48 -> 0 | C22: =RH_SAS!D48 -> 0 | D22: =RH_SAS!E48 -> 0 | E22: =IF(B22=0,"-",C22/B22-1) -> - | F22: =IF(C22=0,"-",D22/C22-1) -> -
A23: Masse salariale brute (FCFA) | B23: =RH_SAS!C70 -> 0 | C23: =RH_SAS!D70 -> 0 | D23: =RH_SAS!E70 -> 0 | E23: =IF(B23=0,"-",C23/B23-1) -> - | F23: =IF(C23=0,"-",D23/C23-1) -> -
A24: Cotisations IPRES employeur (FCFA) | B24: =RH_SAS!C71 -> 0 | C24: =RH_SAS!D71 -> 0 | D24: =RH_SAS!E71 -> 0 | E24: =IF(B24=0,"-",C24/B24-1) -> - | F24: =IF(C24=0,"-",D24/C24-1) -> -
A25: Cotisations CSS employeur (FCFA) | B25: =RH_SAS!C72 -> 0 | C25: =RH_SAS!D72 -> 0 | D25: =RH_SAS!E72 -> 0 | E25: =IF(B25=0,"-",C25/B25-1) -> - | F25: =IF(C25=0,"-",D25/C25-1) -> -
A26: Coût total employeur (FCFA) | B26: =RH_SAS!C73 -> 0 | C26: =RH_SAS!D73 -> 0 | D26: =RH_SAS!E73 -> 0 | E26: =IF(B26=0,"-",C26/B26-1) -> - | F26: =IF(C26=0,"-",D26/C26-1) -> -
A28: SYNTHÈSE FISCALE — IS / TVA / Patente (spécificité SAS sénégalaise)
A29: Chiffre d'affaires HT (FCFA) | B29: =FINANCES!C5 -> 0 | C29: =FINANCES!D5 -> 0 | D29: =FINANCES!E5 -> 0
A30: Résultat avant IS (FCFA) | B30: =FINANCES!C32 -> 0 | C30: =FINANCES!D32 -> 0 | D30: =FINANCES!E32 -> 0
A31: IS dû (30% du résultat) | B31: =FINANCES!C34 -> 0 | C31: =FINANCES!D34 -> 0 | D31: =FINANCES!E34 -> 0
A32: IMF minimum si déficit (500k-5M FCFA) | B32: =FINANCES!C35 -> 0 | C32: =FINANCES!D35 -> 0 | D32: =FINANCES!E35 -> 0
A33: TVA collectée | B33: =FINANCES!C38 -> 0 | C33: =FINANCES!D38 -> 0 | D33: =FINANCES!E38 -> 0
A34: TVA déductible | B34: =FINANCES!C39 -> 0 | C34: =FINANCES!D39 -> 0 | D34: =FINANCES!E39 -> 0
A35: TVA nette à reverser | B35: =FINANCES!C40 -> 0 | C35: =FINANCES!D40 -> 0 | D35: =FINANCES!E40 -> 0

Sheet IDENTITE
A1: IDENTITÉ SOCIÉTÉ — SAS DE DROIT OHADA (Sénégal)
A2: ⚡ SAS = Société par Actions Simplifiée | Cadre juridique : Acte Uniforme OHADA sur les sociétés commerciales (révisé 2014)
A3: Champs verts = spécificités SAS sénégalaise | Bleu = à saisir | Noir = formule
D4: DOCUMENTS CONSTITUTIFS & LICENCES
A5: INFORMATIONS GÉNÉRALES — SAS OHADA | D5: Document | E5: Numéro / statut
A6: Dénomination sociale | D6: Statuts SAS enregistrés (RCCM)
A7: Forme juridique | B7: SAS — Société par Actions Simplifiée (OHADA) | D7: Procès-verbal constitutif
A8: NINEA (Numéro d'identification national) | D8: Règlement intérieur (si applicable)
A9: Numéro RCCM (Registre Commerce et Crédit Mobilier) | D9: Déclaration d'établissement (Inspection Travail)
A10: Date d'immatriculation au RCCM | D10: Autorisation d'exercer (selon secteur)
A11: Capital social (FCFA) | D11: Agrément spécifique (musique, spectacle, audiovisuel)
A12: Siège social (adresse complète Dakar / ville) | D12: Agrément Code des Investissements (si applicable)
A13: Activité principale
A14: Code SYSCOA / activité | D14: DATES CLÉS À SURVEILLER
A15: Date de création | D15: Obligation | E15: Date échéance
A16: Durée de vie de la société (statuts) | B16: 99 ans (par défaut) | D16: Patente annuelle (avant 31 mars)
D17: Déclaration IS annuelle (avant 30 avril)
A18: DIRECTION ET ACTIONNARIAT — SAS | D18: Déclaration TVA mensuelle
A19: Président de la SAS | D19: Déclaration IPRES annuelle (avant 31 mars)
A20: Directeur Général (si distinct du Président) | D20: Assemblée Générale annuelle
A21: Directeur Général Délégué | D21: Dépôt comptes annuels au RCCM
A22: Email de contact principal | D22: Renouvellement RCCM (si applicable)
A23: Téléphone principal | D23: Autorisation / agrément sectoriel
A24: Site internet
A26: STRUCTURE ACTIONNARIALE | D26: COMPTES BANCAIRES (UEMOA / FCFA)
A27: SAS OHADA : actions librement cessibles selon statuts. Mentionner si actionnariat étranger > 10% (obligations déclaratives APIX). | D27: Banque | E27: IBAN / RIB local
A28: Actionnaire | B28: % détenu | D28: Compte principal opérations
D29: Compte épargne
D30: Autre

Sheet ORGANISMES
A1: ORGANISMES SOCIAUX & FISCAUX — SAS SÉNÉGALAISE (cadre OHADA)
A2: Système sénégalais : IPRES (retraite) + CSS (sécurité sociale) + IPM (maladie) + DGI (impôts). ≠ système français (URSSAF/GUSO/Audiens/AFDAS).
A3: Chaque organisme = un bloc. Renseigner n° adhérent, date d'échéance, vérifier cohérence des informations déclarées.
A4: Organisme | B4: Compte ouvert ? | C4: N° adhérent / identifiant | D4: Date expiration / échéance | E4: Infos à jour ? | F4: Dernière vérification | G4: Alerte automatique | H4: Contact / interlocuteur
A5: PATENTE — Contribution économique locale (annuelle, avant 31 mars)
A6: Numéro de patente (délivré par la DGI) | B6: Oui | E6: Oui | G6: =IFERROR(IF(D6="","—",IF(D6<TODAY(),"EXPIRÉ",IF(D6<TODAY()+90,"URGENT < 3 mois",IF(D6<TODAY()+180,"Attention < 6 mois","OK — "&TEXT(D6,"MM/YYYY"))))),"—") -> —
A7: Droit fixe selon activité et CA | B7: Oui | E7: Oui | G7: =IFERROR(IF(D7="","—",IF(D7<TODAY(),"EXPIRÉ",IF(D7<TODAY()+90,"URGENT < 3 mois",IF(D7<TODAY()+180,"Attention < 6 mois","OK — "&TEXT(D7,"MM/YYYY"))))),"—") -> —
A8: Droit proportionnel sur valeur locative locaux | B8: Oui | E8: Oui | G8: =IFERROR(IF(D8="","—",IF(D8<TODAY(),"EXPIRÉ",IF(D8<TODAY()+90,"URGENT < 3 mois",IF(D8<TODAY()+180,"Attention < 6 mois","OK — "&TEXT(D8,"MM/YYYY"))))),"—") -> —
A9: NINEA — Numéro d'identification national (DGID / APIX)
A10: Numéro NINEA (identifiant unique entreprise) | B10: Oui | E10: Oui | G10: =IFERROR(IF(D10="","—",IF(D10<TODAY(),"EXPIRÉ",IF(D10<TODAY()+90,"URGENT < 3 mois",IF(D10<TODAY()+180,"Attention < 6 mois","OK — "&TEXT(D10,"MM/YYYY"))))),"—") -> —
A11: Mise à jour informations (adresse, dirigeant, activité) | B11: Oui | E11: Oui | G11: =IFERROR(IF(D11="","—",IF(D11<TODAY(),"EXPIRÉ",IF(D11<TODAY()+90,"URGENT < 3 mois",IF(D11<TODAY()+180,"Attention < 6 mois","OK — "&TEXT(D11,"MM/YYYY"))))),"—") -> —
A12: IPRES — Institut de Prévoyance Retraite du Sénégal
A13: N° adhérent IPRES (Régime Général — RG) — taux 14% (8,4% patronal + 5,6% salarial) plafond 432k FCFA/mois | B13: Oui | E13: Oui | G13: =IFERROR(IF(D13="","—",IF(D13<TODAY(),"EXPIRÉ",IF(D13<TODAY()+90,"URGENT < 3 mois",IF(D13<TODAY()+180,"Attention < 6 mois","OK — "&TEXT(D13,"MM/YYYY"))))),"—") -> —
A14: N° adhérent IPRES (Régime Complémentaire — RC cadres) — taux 6% plafond 1,296M FCFA/mois | B14: Oui | E14: Oui | G14: =IFERROR(IF(D14="","—",IF(D14<TODAY(),"EXPIRÉ",IF(D14<TODAY()+90,"URGENT < 3 mois",IF(D14<TODAY()+180,"Attention < 6 mois","OK — "&TEXT(D14,"MM/YYYY"))))),"—") -> —
A15: Déclaration annuelle des salaires (avant 31 mars) | B15: Oui | E15: Oui | G15: =IFERROR(IF(D15="","—",IF(D15<TODAY(),"EXPIRÉ",IF(D15<TODAY()+90,"URGENT < 3 mois",IF(D15<TODAY()+180,"Attention < 6 mois","OK — "&TEXT(D15,"MM/YYYY"))))),"—") -> —
A16: CSS — Caisse de Sécurité Sociale (accidents travail + prestations familiales)
A17: N° immatriculation CSS (obligatoire dans 2 mois après 1er salarié) | B17: Oui | E17: Oui | G17: =IFERROR(IF(D17="","—",IF(D17<TODAY(),"EXPIRÉ",IF(D17<TODAY()+90,"URGENT < 3 mois",IF(D17<TODAY()+180,"Attention < 6 mois","OK — "&TEXT(D17,"MM/YYYY"))))),"—") -> —
A18: Prestations familiales — taux 7% plafonné 63k FCFA/mois (100% patronal) | B18: Oui | E18: Oui | G18: =IFERROR(IF(D18="","—",IF(D18<TODAY(),"EXPIRÉ",IF(D18<TODAY()+90,"URGENT < 3 mois",IF(D18<TODAY()+180,"Attention < 6 mois","OK — "&TEXT(D18,"MM/YYYY"))))),"—") -> —
A19: Accidents du travail — taux 1%, 3% ou 5% selon secteur (100% patronal) | B19: Oui | E19: Oui | G19: =IFERROR(IF(D19="","—",IF(D19<TODAY(),"EXPIRÉ",IF(D19<TODAY()+90,"URGENT < 3 mois",IF(D19<TODAY()+180,"Attention < 6 mois","OK — "&TEXT(D19,"MM/YYYY"))))),"—") -> —
A20: Déclaration trimestrielle des effectifs et salaires | B20: Oui | E20: Oui | G20: =IFERROR(IF(D20="","—",IF(D20<TODAY(),"EXPIRÉ",IF(D20<TODAY()+90,"URGENT < 3 mois",IF(D20<TODAY()+180,"Attention < 6 mois","OK — "&TEXT(D20,"MM/YYYY"))))),"—") -> —
A21: IPM — Institution de Prévoyance Maladie (mutuelle santé)
A22: N° adhérent IPM (assurance maladie salarié + famille) | B22: Oui | E22: Oui | G22: =IFERROR(IF(D22="","—",IF(D22<TODAY(),"EXPIRÉ",IF(D22<TODAY()+90,"URGENT < 3 mois",IF(D22<TODAY()+180,"Attention < 6 mois","OK — "&TEXT(D22,"MM/YYYY"))))),"—") -> —
A23: Cotisation répartie employeur/salarié (taux variable selon IPM) | B23: Oui | E23: Oui | G23: =IFERROR(IF(D23="","—",IF(D23<TODAY(),"EXPIRÉ",IF(D23<TODAY()+90,"URGENT < 3 mois",IF(D23<TODAY()+180,"Attention < 6 mois","OK — "&TEXT(D23,"MM/YYYY"))))),"—") -> —
A24: Carte de soins des salariés à jour | B24: Oui | E24: Oui | G24: =IFERROR(IF(D24="","—",IF(D24<TODAY(),"EXPIRÉ",IF(D24<TODAY()+90,"URGENT < 3 mois",IF(D24<TODAY()+180,"Attention < 6 mois","OK — "&TEXT(D24,"MM/YYYY"))))),"—") -> —
A25: INSPECTION DU TRAVAIL — Déclaration d'établissement
A26: Déclaration d'établissement déposée à l'Inspection régionale du travail | B26: Oui | E26: Oui | G26: =IFERROR(IF(D26="","—",IF(D26<TODAY(),"EXPIRÉ",IF(D26<TODAY()+90,"URGENT < 3 mois",IF(D26<TODAY()+180,"Attention < 6 mois","OK — "&TEXT(D26,"MM/YYYY"))))),"—") -> —
A27: Registre de paie tenu et disponible | B27: Oui | E27: Oui | G27: =IFERROR(IF(D27="","—",IF(D27<TODAY(),"EXPIRÉ",IF(D27<TODAY()+90,"URGENT < 3 mois",IF(D27<TODAY()+180,"Attention < 6 mois","OK — "&TEXT(D27,"MM/YYYY"))))),"—") -> —
A28: Règlement intérieur affiché (obligatoire si > 20 salariés) | B28: Oui | E28: Oui | G28: =IFERROR(IF(D28="","—",IF(D28<TODAY(),"EXPIRÉ",IF(D28<TODAY()+90,"URGENT < 3 mois",IF(D28<TODAY()+180,"Attention < 6 mois","OK — "&TEXT(D28,"MM/YYYY"))))),"—") -> —
A29: RCCM — Registre du Commerce et du Crédit Mobilier
A30: Numéro RCCM (à afficher sur tous documents commerciaux) | B30: Oui | E30: Oui | G30: =IFERROR(IF(D30="","—",IF(D30<TODAY(),"EXPIRÉ",IF(D30<TODAY()+90,"URGENT < 3 mois",IF(D30<TODAY()+180,"Attention < 6 mois","OK — "&TEXT(D30,"MM/YYYY"))))),"—") -> —
A31: Mise à jour en cas de modification statutaire (dirigeant, siège, capital) | B31: Oui | E31: Oui | G31: =IFERROR(IF(D31="","—",IF(D31<TODAY(),"EXPIRÉ",IF(D31<TODAY()+90,"URGENT < 3 mois",IF(D31<TODAY()+180,"Attention < 6 mois","OK — "&TEXT(D31,"MM/YYYY"))))),"—") -> —
A32: Dépôt comptes annuels au greffe (dans 30 jours après AG) | B32: Oui | E32: Oui | G32: =IFERROR(IF(D32="","—",IF(D32<TODAY(),"EXPIRÉ",IF(D32<TODAY()+90,"URGENT < 3 mois",IF(D32<TODAY()+180,"Attention < 6 mois","OK — "&TEXT(D32,"MM/YYYY"))))),"—") -> —
A33: DGI / DGID — Direction Générale des Impôts
A34: IS — Impôt sur les Sociétés 30% (déclaration avant 30 avril) | B34: Oui | E34: Oui | G34: =IFERROR(IF(D34="","—",IF(D34<TODAY(),"EXPIRÉ",IF(D34<TODAY()+90,"URGENT < 3 mois",IF(D34<TODAY()+180,"Attention < 6 mois","OK — "&TEXT(D34,"MM/YYYY"))))),"—") -> —
A35: IMF — Impôt Minimum Forfaitaire (si déficit : 500k à 5M FCFA selon CA) | B35: Oui | E35: Oui | G35: =IFERROR(IF(D35="","—",IF(D35<TODAY(),"EXPIRÉ",IF(D35<TODAY()+90,"URGENT < 3 mois",IF(D35<TODAY()+180,"Attention < 6 mois","OK — "&TEXT(D35,"MM/YYYY"))))),"—") -> —
A36: TVA — Taxe sur Valeur Ajoutée 18% (déclaration mensuelle, taux réduit 10% tourisme) | B36: Oui | E36: Oui | G36: =IFERROR(IF(D36="","—",IF(D36<TODAY(),"EXPIRÉ",IF(D36<TODAY()+90,"URGENT < 3 mois",IF(D36<TODAY()+180,"Attention < 6 mois","OK — "&TEXT(D36,"MM/YYYY"))))),"—") -> —
A37: TRIMF — retenue à la source sur salaires (barème progressif annuel) | B37: Oui | E37: Oui | G37: =IFERROR(IF(D37="","—",IF(D37<TODAY(),"EXPIRÉ",IF(D37<TODAY()+90,"URGENT < 3 mois",IF(D37<TODAY()+180,"Attention < 6 mois","OK — "&TEXT(D37,"MM/YYYY"))))),"—") -> —
A38: Retenue à source prestataires étrangers 20% (si pas d'installation au Sénégal) | B38: Oui | E38: Oui | G38: =IFERROR(IF(D38="","—",IF(D38<TODAY(),"EXPIRÉ",IF(D38<TODAY()+90,"URGENT < 3 mois",IF(D38<TODAY()+180,"Attention < 6 mois","OK — "&TEXT(D38,"MM/YYYY"))))),"—") -> —
A40: COHÉRENCE DES INFORMATIONS — Vérifier identité entre tous les organismes
A41: Les informations déclarées chez chaque organisme doivent être IDENTIQUES. Tout changement doit être déclaré dans les 30 jours.
...

Sheet RH_SAS
A1: MOYENS HUMAINS — SAS SÉNÉGALAISE — N-1 / N / N+1
A2: Calcul des charges sociales selon le droit sénégalais : IPRES RG + IPRES RC (cadres) + CSS (prestations familiales + accidents travail)
A4: TAUX DE CHARGES SOCIALES SÉNÉGALAIS (modifiables si évolution réglementaire)
A5: Organisme / Cotisation | B5: Assiette plafond mensuel | C5: Taux total | D5: Part patronale | E5: Part salariale | F5: Qui est concerné | G5: Note
A6: IPRES RG — Retraite de base | B6: 432 000 FCFA/mois | C6: 0.14 | D6: 0.084 | E6: 0.056 | F6: Tous salariés | G6: IPRES paramètres 2025
A7: IPRES RC — Retraite compl. cadres | B7: 1 296 000 FCFA/mois | C7: 0.06 | D7: 0.036 | E7: 0.024 | F7: Cadres uniquement | G7: Régime complémentaire
A8: CSS — Prestations familiales | B8: 63 000 FCFA/mois | C8: 0.07 | D8: 0.07 | E8: 0 | F8: Tous salariés | G8: 100% patronal
A9: CSS — Accidents du travail | B9: 63 000 FCFA/mois | C9: 0.03 | D9: 0.03 | E9: 0 | F9: Tous salariés | G9: 1%, 3% ou 5% selon secteur
A10: TRIMF — Impôt min. fiscal | B10: Salaire brut annuel | C10: Barème | D10: Barème | E10: Barème | F10: Tous salariés | G10: Retenue à la source progressive
A12: SALARIÉS PERMANENTS — CDI / CDD
A13: Poste / Fonction | B13: Statut / Type | C13: N-1 ETPT | D13: N ETPT | E13: N+1 ETPT | F13: Quotité N | G13: Cadre ?
A14: Président / Directeur Général | B14: CDI | G14: Non
A15: Directeur Artistique | B15: CDI | G15: Non
A16: Administrateur de Production | B16: CDI | G16: Non
A17: Chargé(e) de Production | B17: CDI | G17: Non
A18: Chargé(e) de Communication | B18: CDI | G18: Non
A19: Assistant(e) de Gestion | B19: CDI | G19: Non
A20: Autre poste 1 | B20: CDI | G20: Non
A21: Autre poste 2 | B21: CDI | G21: Non
A22: SOUS-TOTAL ETPT PERMANENTS | C22: =SUM(C14:C21) -> 0 | D22: =SUM(D14:D21) -> 0 | E22: =SUM(E14:E21) -> 0
A24: PRESTATAIRES & INTERVENANTS (contexte sénégalais : pas d'intermittent GUSO)
A25: Au Sénégal : pas de régime intermittent du spectacle comme en France. Les artistes sont payés en cachets (CDD, contrat de prestation, ou contrat d'artiste du spectacle selon Code du Travail sénégalais).
A26: Nom / Artiste | B26: Type de contrat | C26: Nb jours | D26: Cachet/jr (FCFA) | E26: Brut total (FCFA) | F26: Charges IPRES+CSS | G26: Coût total (FCFA)
B27: Artiste intervenant (CDD) | E27: =IF(C27*D27=0,0,C27*D27) -> 0 | F27: =E27*0.184 -> 0 | G27: =E27+F27 -> 0
B28: Artiste intervenant (CDD) | E28: =IF(C28*D28=0,0,C28*D28) -> 0 | F28: =E28*0.184 -> 0 | G28: =E28+F28 -> 0
B29: Prestataire (contrat prestation) | E29: =IF(C29*D29=0,0,C29*D29) -> 0 | F29: =E29*0.184 -> 0 | G29: =E29+F29 -> 0
B30: Prestataire (contrat prestation) | E30: =IF(C30*D30=0,0,C30*D30) -> 0 | F30: =E30*0.184 -> 0 | G30: =E30+F30 -> 0
B31: Technicien (CDD) | E31: =IF(C31*D31=0,0,C31*D31) -> 0 | F31: =E31*0.184 -> 0 | G31: =E31+F31 -> 0
A32: TOTAL PRESTATAIRES INTERVENANTS | E32: =SUM(E27:E31) -> 0 | F32: =SUM(F27:F31) -> 0 | G32: =SUM(G27:G31) -> 0
A34: RÉCAPITULATIF MASSE SALARIALE — N-1 / N / N+1
A35: Poste | C35: N-1 | D35: N | E35: N+1
A36: ETPT permanents | C36: =C22 -> 0 | D36: =D22 -> 0 | E36: =E22 -> 0
A37: Masse salariale brute permanents (FCFA)
A38: IPRES patronal permanents (~12% plafonné)
A39: CSS patronal permanents (~10%)
A40: Coût total employeur permanents
A41: Coût total intervenants | C41: =G32 -> 0 | D41: =G32 -> 0 | E41: =G32 -> 0
A43: COÛT TOTAL EMPLOYEUR GLOBAL (FCFA) | D43: =D40+G32 -> 0

Sheet FINANCES
A1: COMPTE DE RÉSULTAT PRÉVISIONNEL — SAS SÉNÉGALAISE (plan SYSCOA/OHADA)
A2: Monnaie : FCFA | Plan comptable SYSCOA (Système Comptable OHADA) | ≠ Plan comptable général français
A3: N-1 = bilan certifié | N = prévisionnel en cours | N+1 = projection | Dépôt comptes annuels obligatoire au RCCM dans 30j après AG
A4: PRODUITS (SYSCOA) | C4: N-1 réalisé | D4: N prévisionnel | E4: N+1 projection | F4: Note
A5: 70 — Ventes de marchandises
A6: 701 Ventes marchandises
A7: 71 — Ventes de services (prestations culturelles)
A8: 706 Prestations de services / cachets artistiques
A9: 708 Autres produits d'activités
A10: 74 — Subventions d'exploitation
A11: 741 Subventions d'exploitation État sénégalais
A12: 742 Subventions collectivités territoriales
A13: 743 Subventions organismes internationaux / AFD
A14: 748 Autres subventions
A15: 75 — Autres produits
A16: 754 Dons et mécénat
... A19: 771 Intérêts et produits assimilés
A20: TOTAL PRODUITS HT | C20: =C6+C8+C9+C11+C12+C13+C14+C16+C17+C19 -> 0 | D20: =D6+D8+D9+D11+D12+D13+D14+D16+D17+D19 -> 0 | E20: =E6+E8+E9+E11+E12+E13+E14+E16+E17+E19 -> 0
A22: CHARGES (SYSCOA) | C22: N-1 réalisé | D22: N prévisionnel | E22: N+1 projection | F22: Note
A23: 60 — Achats de marchandises et mat.
A24: 601/606 Achats matières et fournitures
A25: 61-62 — Services extérieurs
A26: 613 Locations
A27: 615 Entretien et réparations
A28: 616 Assurances
A29: 622 Honoraires
A30: 623 Communication
A31: 625 Déplacements et transports
A32: 628 Autres services
A33: 64 — Charges de personnel
A34: 641 Salaires et rémunérations bruts
... A46: 681 Amortissements immobilisations
A47: TOTAL CHARGES HT | C47: =C24+C26+C27+C28+C29+C30+C31+C32+C34+C35+C36+C37+C39+C40+C42+C44+C46 -> 0 | D47: =D24+D26+D27+D28+D29+D30+D31+D32+D34+D35+D36+D37+D39+D40+D42+D44+D46 -> 0 | E47: =E24+E26+E27+E28+E29+E30+E31+E32+E34+E35+E36+E37+E39+E40+E42+E44+E46 -> 0
A49: RÉSULTAT ET FISCALITÉ — IS 30% / IMF (spécificité SAS sénégalaise)
A50: RÉSULTAT AVANT IS | C50: =C20-C47 -> 0 | D50: =D20-D47 -> 0 | E50: =E20-E47 -> 0
A51: IS — Impôt sur les Sociétés (30% du résultat si bénéfice) | C51: =MAX(C50*0.3,0) -> 0 | D51: =MAX(D50*0.3,0) -> 0 | E51: =MAX(E50*0.3,0) -> 0
A52: IMF — Impôt Min. Forfaitaire si déficit (500k-5M FCFA selon CA) | C52: =IF(C50<0,"500 000 à 5 000 000 FCFA selon CA","-") -> - | D52: =IF(D50<0,"500 000 à 5 000 000 FCFA selon CA","-") -> - | E52: =IF(E50<0,"500 000 à 5 000 000 FCFA selon CA","-") -> -
A53: RÉSULTAT NET APRÈS IS | C53: =C50-C51 -> 0 | D53: =D50-D51 -> 0 | E53: =E50-E51 -> 0
A55: TVA SÉNÉGALAISE — Taux normal 18% / Taux réduit 10%
A56: Déclaration mensuelle obligatoire. Taux normal 18% (majorité prestations). Taux réduit 10% (tourisme, hôtellerie). Exportations 0%. Exonérations : santé, éducation, banque.
...

Sheet COLLECTE_DOCS
A1: MODÈLE DE COLLECTE DOCUMENTS — SAS SÉNÉGALAISE (cadre OHADA)
A2: Documents à demander au client avant RDV et avant signature de contrat de prestation
A4: Document / Information | B4: Priorité | C4: Format attendu | D4: Reçu ? | E4: Date réception | F4: Pourquoi nécessaire
A5: PIÈCES CONSTITUTIVES & JURIDIQUES OHADA
A6: Statuts de la SAS enregistrés au RCCM | B6: Obligatoire | C6: PDF | D6: Non | F6: Existence juridique OHADA
A7: Extrait RCCM récent (moins de 3 mois) | B7: Obligatoire | C7: PDF | D7: Non | F7: Identité commerciale
A8: NINEA (avis d'immatriculation DGID) | B8: Obligatoire | C8: PDF | D8: Non | F8: Identifiant fiscal
A9: Procès-verbal constitutif / AG constitutive | B9: Obligatoire | C9: PDF | D9: Non | F9: Gouvernance SAS
A10: Liste des dirigeants (Président, DG si applicable) | B10: Obligatoire | C10: PDF | D10: Non | F10: Représentation légale
A11: Déclaration d'établissement (Inspection Travail) | B11: Obligatoire si salariés | C11: PDF | D11: Non | F11: Obligation légale employeur
A12: PIÈCES FISCALES
A13: Attestation de régularité fiscale (DGI) | B13: Obligatoire | C13: PDF | D13: Non | F13: Conformité IS / TVA
A14: Dernière déclaration IS signée | B14: Si disponible | C14: PDF | D14: Non | F14: Situation fiscale
A15: Attestation NINEA à jour | B15: Obligatoire | C15: PDF | D15: Non | F15: Vérification activité déclarée
A16: Agrément sectoriel (musique, spectacle, audiovisuel si requis) | B16: Si applicable | C16: PDF | D16: Non | F16: Autorisation d'exercer
A17: PIÈCES COMPTABLES & FINANCIÈRES (plan SYSCOA)
A18: Bilan SYSCOA N-1 certifié | B18: Obligatoire | C18: PDF/Excel | D18: Non | F18: Faisabilité financière
A19: Compte de résultat N-1 | B19: Obligatoire | C19: PDF/Excel | D19: Non | F19: Faisabilité financière
A20: Bilan N-2 si disponible | B20: Recommandé | C20: PDF/Excel | D20: Non | F20: Historique financier
A21: Budget prévisionnel N (plan SYSCOA) | B21: Obligatoire | C21: Excel | D21: Non | F21: Dossier de financement
A22: Situation trésorerie récente (solde bancaire FCFA) | B22: Recommandé | C22: PDF | D22: Non | F22: Capacité préfinancement
A23: PIÈCES SOCIALES — IPRES / CSS
A24: Attestation de régularité IPRES | B24: Obligatoire si salariés | C24: PDF | D24: Non | F24: Conformité retraite
A25: Attestation de régularité CSS | B25: Obligatoire si salariés | C25: PDF | D25: Non | F25: Conformité sécu sociale
A26: N° adhérent IPRES + N° adhérent CSS | B26: Obligatoire | C26: Identifiants | D26: Non | F26: Vérification affiliation
A27: Contrat IPM (mutuelle maladie) | B27: Si salariés | C27: PDF | D27: Non | F27: Obligation employeur
A28: Registre de paie (à disposition) | B28: Obligatoire légalement | C28: Registre | D28: Non | F28: Obligation droit travail sénégalais
A29: PIÈCES PROJET (en plus des pièces société)
A30: Note artistique et descriptif du projet | B30: Obligatoire | C30: PDF | D30: Non | F30: Dossier artistique
A31: Programmation prévisionnelle | B31: Obligatoire | C31: PDF | D31: Non | F31: Financement
A32: Liste des artistes / intervenants avec cachets | B32: Obligatoire | C32: Excel | D32: Non | F32: Budget RH
A33: Lettre d'engagement ou contrat lieu de diffusion | B33: Obligatoire | C33: PDF | D33: Non | F33: Dossier financement
A34: Demandes de financement en cours (ACC, FONAC, bailleurs) | B34: Si disponibles | C34: PDF | D34: Non | F34: Plan financement
A35: Contrats artistes signés (contrats d'artiste du spectacle) | B35: Si disponibles | C35: PDF | D35: Non | F35: Conformité salariale
A36: SPÉCIFICITÉS FINANCEMENT SÉNÉGALAIS / AFRICAIN
A37: FONAC — Fonds National pour la Culture (si demandé) | B37: Si applicable | C37: PDF | D37: Non | F37: Financement culturel sénégalais
A38: ADPME / APIX — Dossier investissement (si applicable) | B38: Si applicable | C38: PDF | D38: Non | F38: Agences publiques sénégalaises
A39: Financement diaspora ou partenaires internationaux | B39: Si applicable | C39: Justificatifs | D39: Non | F39: Axe international
A40: Convention UEMOA (si activités régionales) | B40: Si applicable | C40: PDF | D40: Non | F40: Zone CEDEAO / UEMOA
A41: Accord de coproduction internationale (France, UK, etc.) | B41: Si applicable | C41: PDF | D41: Non | F41: Partenariats internationaux
...
